Workbook

Sheet Summary
A1: BLACK AESTHETICS — PRODUCT LOG (3D website vs live Shopify)
A2: Generated 2026-07-12 from Shopify Admin MCP — blackaestheticspk.com (PKR)
A4: Live Shopify products (all) | B4: =COUNTA('Shopify Live Products'!B2:B100000) -> 506
A5: Shopify products with status ACTIVE | B5: =COUNTIF('Shopify Live Products'!D2:D100000,"ACTIVE") -> 503
A6: Shopify products in DRAFT | B6: =COUNTIF('Shopify Live Products'!D2:D100000,"DRAFT") -> 3
A7: Shopify collections | B7: 38
A8: Products in the 3D website | B8: =COUNTA('3D Website Products'!A2:A100000) -> 198
A9: 3D products matched to a live Shopify product | B9: =COUNTIF('3D Website Products'!G2:G100000,TRUE()) -> 173
A10: 3D products with NO live Shopify product | B10: =COUNTIF('3D Website Products'!G2:G100000,FALSE()) -> 25
A11: Live Shopify products shown in the 3D website | B11: =COUNTIF('Shopify Live Products'!S2:S100000,TRUE()) -> 166
A12: Live Shopify products NOT yet in the 3D website | B12: =COUNTIF('Shopify Live Products'!S2:S100000,FALSE()) -> 340
A14: Purpose: emulate live Shopify data inside the 3D website so Storefront checkout wiring is a drop-in step.
A15: Machine-readable version: docs/SHOPIFY_PRODUCT_ALIGNMENT.json (collection order, handles, variant IDs, matches).

Sheet Shopify Live Products
A1: Title | B1: Handle | C1: Product GID | D1: Status | E1: Vendor | F1: Type | G1: Tags | H1: Collections | I1: Price Min (PKR) | J1: Price Max (PKR) | K1: Inventory | L1: Variant Count | M1: Variants (title @ price (qty)) | N1: First Variant GID | O1: Available | P1: Featured Image | Q1: Created | R1: Published | S1: In 3D Website | T1: Local Product ID | U1: Local Category | V1: Local Asset | W1: Match Confidence
A2: Blue Lightening Dragon | B2: blue-lightening-dragon | C2: gid://shopify/Product/7405669711971 | D2: ACTIVE | E2: Black Aesthetics | G2: Digital Art, Poster | H2: Modern Art | Digital Art | I2: 3500 | J2: 5600 | K2: 0 | L2: 4 | M2: 6x9 inches @ 3500.00 (0) | 8x12 inches @ 4200.00 (0) | 12x18 inches @ 5000.00 (0) | 18x24 inhces @ 5600.00 (0) | N2: gid://shopify/ProductVariant/42125524926563 | O2: =TRUE() -> TRUE | P2: https://cdn.shopify.com/s/files/1/0572/0077/1171/files/Artboard9_06ac12e1-600a-45a3-973f-6d450d881301.png?v=1756315786 | Q2: 2024-05-01 | R2: 2024-05-01 | S2: =FALSE() -> FALSE
A3: Dogg | B3: dogg | C3: gid://shopify/Product/7405738131555 | D3: ACTIVE | E3: Black Aesthetics | G3: Digital Art, Poster | H3: Personalities | Digital Art | Best Sellers | I3: 3500 | J3: 5600 | K3: 0 | L3: 4 | M3: 6x9 inches @ 3500.00 (0) | 8x12 inches @ 4200.00 (0) | 12x18 inches @ 5000.00 (0) | 18x24 inches @ 5600.00 (0) | N3: gid://shopify/ProductVariant/43541219934307 | O3: =TRUE() -> TRUE | P3: https://cdn.shopify.com/s/files/1/0572/0077/1171/files/Artboard9_3dc097da-9f05-452a-9c37-f7795ed0060a.png?v=1756330441 | Q3: 2024-05-01 | R3: 2024-05-01 | S3: =FALSE() -> FALSE
A4: Eagle Attack | B4: eagle-attack | C4: gid://shopify/Product/7405752811619 | D4: ACTIVE | E4: Black Aesthetics | G4: Digital Art, Poster | H4: Animals | Digital Art | I4: 3500 | J4: 5600 | K4: 0 | L4: 4 | M4: 6x9 inches @ 3500.00 (0) | 8x12 inches @ 4200.00 (0) | 12x18 inches @ 5000.00 (0) | 18x24 inches @ 5600.00 (0) | N4: gid://shopify/ProductVariant/42125594656867 | O4: =TRUE() -> TRUE | P4: https://cdn.shopify.com/s/files/1/0572/0077/1171/files/Artboard_6_91addfea-d8c7-4689-b69d-4cba8fbde1f8.png?v=1756385750 | Q4: 2024-05-01 | R4: 2024-05-01 | S4: =FALSE() -> FALSE
A5: Goku | B5: goku | C5: gid://shopify/Product/7405755367523 | D5: ACTIVE | E5: Black Aesthetics | G5: Digital Art, Poster | H5: Anime/Manga | Digital Art | Dragon Ball | Anime/Manga- Digital Art | I5: 3500 | J5: 5600 | K5: 0 | L5: 4 | M5: 6x9 inches @ 3500.00 (0) | 8x12 inches @ 4200.00 (0) | 12x18 inches @ 5000.00 (0) | 18x24 inches @ 5600.00 (0) | N5: gid://shopify/ProductVariant/43541216165987 | O5: =TRUE() -> TRUE | P5: https://cdn.shopify.com/s/files/1/0572/0077/1171/files/Artboard6_af76b9be-4af0-4641-81a1-21fb384efbd4.png?v=1756407500 | Q5: 2024-05-01 | R5: 2024-05-01 | S5: =FALSE() -> FALSE
A6: Smoking Lady | B6: paki-smoker-ladies | C6: gid://shopify/Product/7405759365219 | D6: ACTIVE | E6: Black Aesthetics | G6: Digital Art, Poster | H6: Digital Art | Best Sellers | Cultural Arts- Digital | Smoking Lady | I6: 3500 | J6: 5600 | K6: 0 | L6: 4 | M6: 6x9 inches @ 3500.00 (0) | 8x12 inches @ 4200.00 (0) | 12x18 inches @ 5000.00 (0) | 18x24 inches @ 5600.00 (0) | N6: gid://shopify/ProductVariant/43541215805539 | O6: =TRUE() -> TRUE | P6: https://cdn.shopify.com/s/files/1/0572/0077/1171/files/Artboard6_97beb49a-d157-4a63-b0d6-db772649836e.png?v=1756495196 | Q6: 2024-05-01 | R6: 2024-05-01 | S6: =TRUE() -> TRUE | T6: digital-smoking-lady-12x18 | U6: digital-art | V6: /products/digital/final/smoking-lady-12x18.jpg | W6: fuzzy
A7: Smoking Lady Variant 2 | B7: paki-smoker-ladies-1 | C7: gid://shopify/Product/7405764018275 | D7: ACTIVE | E7: Black Aesthetics | G7: Digital Art, Poster | H7: Digital Art | Cultural Arts- Digital | Smoking Lady | I7: 3500 | J7: 5600 | K7: 0 | L7: 4 | M7: 6x9 inches @ 3500.00 (-1) | 8x12 inches @ 4200.00 (-1) | 12x18 inches @ 5000.00 (0) | 16x24 inches @ 5600.00 (-1) | N7: gid://shopify/ProductVariant/43541215051875 | O7: =TRUE() -> TRUE | P7: https://cdn.shopify.com/s/files/1/0572/0077/1171/files/Smoking_Lady_Variant_2.png?v=1756495423 | Q7: 2024-05-01 | R7: 2024-05-01 | S7: =FALSE() -> FALSE
A8: Whirling Dervish | B8: rumi-whirling-dervishes | C8: gid://shopify/Product/7405765165155 | D8: ACTIVE | E8: Black Aesthetics | G8: Digital Art, Poster | H8: Digital Art | Cultural Arts | Cultural Arts- Digital | I8: 3500 | J8: 5600 | K8: 0 | L8: 4 | M8: 6x9 inches @ 3500.00 (0) | 8x12 inches @ 4200.00 (0) | 12x18 inches @ 5000.00 (0) | 16x24 inches @ 5600.00 (-1) | N8: gid://shopify/ProductVariant/43541214265443 | O8: =TRUE() -> TRUE | P8: https://cdn.shopify.com/s/files/1/0572/0077/1171/files/Whirling_Dervish.png?v=1756496907 | Q8: 2024-05-01 | R8: 2024-05-01 | S8: =TRUE() -> TRUE | T8: digital-whirling-dervish | U8: digital-art | V8: /products/digital/final/whirling-dervish.jpg | W8: exact
A9: Whirling Dervish Variant 2 | B9: rumi-whirling-dervishes-1 | C9: gid://shopify/Product/7405766312035 | D9: ACTIVE | E9: Black Aesthetics | G9: Digital Art, Poster | H9: Digital Art | Best Sellers | Cultural Arts | Cultural Arts- Digital | I9: 3500 | J9: 5600 | K9: 0 | L9: 4 | M9: 6x9 inches @ 3500.00 (-1) | 8x12 inches @ 4200.00 (0) | 12x18 inches @ 5000.00 (0) | 16x24 inches @ 5600.00 (-1) | N9: gid://shopify/ProductVariant/43539824869475 | O9: =TRUE() -> TRUE | P9: https://cdn.shopify.com/s/files/1/0572/0077/1171/files/Whirling_Dervish_Variant_2.png?v=1756496986 | Q9: 2024-05-01 | R9: 2024-05-01 | S9: =FALSE() -> FALSE
A10: Adera | B10: adera | C10: gid://shopify/Product/7405777748067 | D10: ACTIVE | E10: Black Aesthetics | H10: 2D Wall-Art | Maths and Nature | Modern Art | I10: 2499 | J10: 2499 | K10: 0 | L10: 1 | M10: 8x24 inches @ 2499.00 (0) | N10: gid://shopify/ProductVariant/41921256980579 | O10: =TRUE() -> TRUE | P10: https://cdn.shopify.com/s/files/1/0572/0077/1171/files/Adera_2a1a0e1a-c26c-4531-a476-6c9ff971d428.png?v=1756236253 | Q10: 2024-05-01 | R10: 2024-05-01 | S10: =TRUE() -> TRUE | T10: wall-adera | U10: wall-art | V10: /products/wall-art/adera.svg | W10: exact
A11: Aries | B11: aries | C11: gid://shopify/Product/7405778927715 | D11: ACTIVE | E11: Black Aesthetics | H11: 2D Wall-Art | Animals | I11: 1999 | J11: 3999 | K11: 0 | L11: 3 | M11: 12x10 inches @ 1999.00 (0) | 18x15 inches @ 2999.00 (0) | 24x20 inches @ 3999.00 (0) | N11: gid://shopify/ProductVariant/41972405305443 | O11: =TRUE() -> TRUE | P11: https://cdn.shopify.com/s/files/1/0572/0077/1171/files/Aries_118e600b-8103-4f7e-b624-fcc682ae470a.png?v=1756237220 | Q11: 2024-05-01 | R11: 2024-05-01 | S11: =TRUE() -> TRUE | T11: wall-aries | U11: wall-art | V11: /products/wall-art/aries.svg | W11: exact
A12: Bull | B12: bull | C12: gid://shopify/Product/7405779452003 | D12: ACTIVE | E12: Black Aesthetics | H12: 2D Wall-Art | Animals | I12: 2499 | J12: 3499 | K12: 0 | L12: 2 | M12: 10x18 inches @ 2499.00 (0) | 14x24 inches @ 3499.00 (0) | N12: gid://shopify/ProductVariant/41965720862819 | O12: =TRUE() -> TRUE | P12: https://cdn.shopify.com/s/files/1/0572/0077/1171/files/Bull_9e89ce67-381b-42d3-b52a-c65b02738557.png?v=1756326830 | Q12: 2024-05-01 | R12: 2024-05-01 | S12: =TRUE() -> TRUE | T12: wall-bull | U12: wall-art | V12: /products/wall-art/bull.svg | W12: exact
A13: Cat | B13: cat | C13: gid://shopify/Product/7405779779683 | D13: ACTIVE | E13: Black Aesthetics | H13: 2D Wall-Art | Animals | I13: 1999 | J13: 3999 | K13: 0 | L13: 3 | M13: 11x12 inches @ 1999.00 (0) | 16x18 inches @ 2999.00 (0) | 22x24 inches @ 3999.00 (0) | N13: gid://shopify/ProductVariant/41867185684579 | O13: =TRUE() -> TRUE | P13: https://cdn.shopify.com/s/files/1/0572/0077/1171/files/Catcopy.png?v=1756327524 | Q13: 2024-05-01 | R13: 2024-05-01 | S13: =TRUE() -> TRUE | T13: wall-cat | U13: wall-art | V13: /products/wall-art/cat.svg | W13: exact
A14: Abstract Cat | B14: cat-1 | C14: gid://shopify/Product/7405780041827 | D14: ACTIVE | E14: Black Aesthetics | H14: 2D Wall-Art | Animals | Modern Art | I14: 1999 | J14: 2499 | K14: 0 | L14: 2 | M14: 6x18 inches @ 1999.00 (0) | 8x24 inches @ 2499.00 (0) | N14: gid://shopify/ProductVariant/41966097662051 | O14: =TRUE() -> TRUE | P14: https://cdn.shopify.com/s/files/1/0572/0077/1171/files/Abstract_Cat.png?v=1756235207 | Q14: 2024-05-01 | R14: 2024-05-01 | S14: =TRUE() -> TRUE | T14: wall-abstract-cat | U14: wall-art | V14: /products/wall-art/abstract-cat.svg | W14: exact
A15: Circle of Life | B15: circle-of-life | C15: gid://shopify/Product/7405780402275 | D15: ACTIVE | E15: Black Aesthetics | H15: 2D Wall-Art | Maths and Nature | Modern Art | Cultural Arts- 2D | I15: 1999 | J15: 3999 | K15: 0 | L15: 3 | M15: 12x12 inches @ 1999.00 (0) | 18x18 inches @ 2999.00 (0) | 24x24 inches @ 3999.00 (-1) | N15: gid://shopify/ProductVariant/41966121255011 | O15: =TRUE() -> TRUE | P15: https://cdn.shopify.com/s/files/1/0572/0077/1171/files/Circle-of-Lifecopy.png?v=1756328139 | Q15: 2024-05-01 | R15: 2024-05-01 | S15: =TRUE() -> TRUE | T15: wall-circle-of-life | U15: wall-art | V15: /products/wall-art/circle-of-life.svg | W15: exact
A16: Cowboy | B16: cowboy | C16: gid://shopify/Product/7405785940067 | D16: ACTIVE | E16: Black Aesthetics | H16: 2D Wall-Art | I16: 5000 | J16: 5600 | K16: 0 | L16: 2 | M16: 12x18 inches @ 5000.00 (0) | 16x24 inches @ 5600.00 (0) | N16: gid://shopify/ProductVariant/41966215397475 | O16: =TRUE() -> TRUE | P16: https://cdn.shopify.com/s/files/1/0572/0077/1171/files/Cowboy_4f2ef5e2-76de-4a45-a2b2-3d75ee441600.png?v=1756328364 | Q16: 2024-05-01 | R16: 2024-05-01 | S16: =TRUE() -> TRUE | T16: wall-cowboy | U16: wall-art | V16: /products/wall-art/cowboy.svg | W16: exact
A17: Hat Lady | B17: daupor | C17: gid://shopify/Product/7405788266595 | D17: ACTIVE | E17: Black Aesthetics | H17: 2D Wall-Art | Minimalistic and Classical Art | Modern Art | I17: 1999 | J17: 3999 | K17: 0 | L17: 3 | M17: 10x12 inches @ 1999.00 (0) | 15x18 inches @ 2999.00 (0) | 20x24 inches @ 3999.00 (0) | N17: gid://shopify/ProductVariant/41966227095651 | O17: =TRUE() -> TRUE | P17: https://cdn.shopify.com/s/files/1/0572/0077/1171/files/Dauporcopy.png?v=1756407815 | Q17: 2024-05-01 | R17: 2024-05-01 | S17: =TRUE() -> TRUE | T17: wall-daupor | U17: wall-art | V17: /products/wall-art/daupor.svg | W17: exact
A18: Deer | B18: deer | C18: gid://shopify/Product/7405789806691 | D18: ACTIVE | E18: Black Aesthetics | H18: 2D Wall-Art | Animals | I18: 5000 | J18: 5600 | K18: 0 | L18: 2 | M18: 12x18 inches @ 5000.00 (0) | 16x24 inches @ 5600.00 (0) | N18: gid://shopify/ProductVariant/41966288175203 | O18: =TRUE() -> TRUE | P18: https://cdn.shopify.com/s/files/1/0572/0077/1171/files/Deercopy.png?v=1756329895 | Q18: 2024-05-01 | R18: 2024-05-01 | S18: =TRUE() -> TRUE | T18: wall-deer | U18: wall-art | V18: /products/wall-art/deer.svg | W18: exact
A19: Flamingo | B19: flamingo | C19: gid://shopify/Product/7405790232675 | D19: ACTIVE | E19: Black Aesthetics | H19: 2D Wall-Art | Animals | I19: 2499 | J19: 3499 | K19: 0 | L19: 2 | M19: 11x18 inches @ 2499.00 (0) | 15x24 inches @ 3499.00 (0) | N19: gid://shopify/ProductVariant/41867211472995 | O19: =TRUE() -> TRUE | P19: https://cdn.shopify.com/s/files/1/0572/0077/1171/files/Front_7248ea9b-340c-466e-9750-2fc5e00fb674.png?v=1739983721 | Q19: 2024-05-01 | R19: 2024-05-01 | S19: =TRUE() -> TRUE | T19: wall-flamingo | U19: wall-art | V19: /products/wall-art/flamingo.svg | W19: exact
A20: Gandalf Staff | B20: gandalf-staff | C20: gid://shopify/Product/7405790462051 | D20: ACTIVE | E20: Black Aesthetics | H20: 2D Wall-Art | Movies | Comics/Superheroes/Movies- 2D | I20: 2999 | J20: 3999 | K20: 0 | L20: 2 | M20: 12x15 inches @ 2999.00 (0) | 20x24 inches @ 3999.00 (0) | N20: gid://shopify/ProductVariant/41867212554339 | O20: =TRUE() -> TRUE | P20: https://cdn.shopify.com/s/files/1/0572/0077/1171/files/Gandalf_Staff.png?v=1756406708 | Q20: 2024-05-01 | R20: 2024-05-01 | S20: =TRUE() -> TRUE | T20: wall-gandalf-staff | U20: wall-art | V20: /products/wall-art/gandalf-staff.svg | W20: exact
A21: Inner Tribal | B21: inner-tribal | C21: gid://shopify/Product/7405790986339 | D21: ACTIVE | E21: Black Aesthetics | H21: 2D Wall-Art | Cultural Arts | Cultural Arts- 2D | I21: 2499 | J21: 5600 | K21: 0 | L21: 2 | M21: 12x16 inches @ 2499.00 (0) | 18x24 inches @ 5600.00 (0) | N21: gid://shopify/ProductVariant/41867214717027 | O21: =TRUE() -> TRUE | P21: https://cdn.shopify.com/s/files/1/0572/0077/1171/files/Inner_Tribal.png?v=1756408844 | Q21: 2024-05-01 | R21: 2024-05-01 | S21: =TRUE() -> TRUE | T21: wall-inner-tribal | U21: wall-art | V21: /products/wall-art/inner-tribal.svg | W21: exact
... A38: Deer Variant 2 | B38: deer-1 | C38: gid://shopify/Product/7407071428707 | D38: ACTIVE | E38: Black Aesthetics | H38: 2D Wall-Art | Animals | I38: 2499 | J38: 3499 | K38: 0 | L38: 2 | M38: 11x18 inches @ 2499.00 (0) | 15x24 inches @ 3499.00 (0) | N38: gid://shopify/ProductVariant/41966304493667 | O38: =TRUE() -> TRUE | P38: https://cdn.shopify.com/s/files/1/0572/0077/1171/files/DeerVariant2.png?v=1756497932 | Q38: 2024-05-02 | R38: 2024-05-02 | S38: =TRUE() -> TRUE | T38: wall-deer-1 | U38: wall-art | V38: /products/wall-art/deer-1.svg | W38: exact
A39: Deer Variant 3 | B39: deer-2 | C39: gid://shopify/Product/7407075524707 | D39: ACTIVE | E39: Black Aesthetics | H39: 2D Wall-Art | Animals | I39: 1999 | J39: 3999 | K39: 0 | L39: 3 | M39: 11x12 inches @ 1999.00 (0) | 17x18 inches @ 2999.00 (0) | 22x24 inches @ 3999.00 (0) | N39: gid://shopify/ProductVariant/41872908288099 | O39: =TRUE() -> TRUE | P39: https://cdn.shopify.com/s/files/1/0572/0077/1171/files/deer-1copy.png?v=1756330113 | Q39: 2024-05-02 | R39: 2024-05-02 | S39: =FALSE() -> FALSE
A40: Deer in forest | B40: deer-in-forest | C40: gid://shopify/Product/7407076540515 | D40: ACTIVE | E40: Black Aesthetics | H40: 2D Wall-Art | Animals | Maths and Nature | I40: 2499 | J40: 2999 | K40: 0 | L40: 2 | M40: 9x18 inches @ 2499.00 (0) | 12x24 inches @ 2999.00 (0) | N40: gid://shopify/ProductVariant/41971255836771 | O40: =TRUE() -> TRUE | P40: https://cdn.shopify.com/s/files/1/0572/0077/1171/files/deer-in-forestcopy.png?v=1756330013 | Q40: 2024-05-02 | R40: 2024-05-02 | S40: =TRUE() -> TRUE | T40: wall-deer-in-forest | U40: wall-art | V40: /products/wall-art/deer-in-forest.svg | W40: exact
A41: Natural Elements | B41: dekoratifctablo | C41: gid://shopify/Product/7407077982307 | D41: ACTIVE | E41: Black Aesthetics | H41: 2D Wall-Art | Modern Art | I41: 1999 | J41: 3999 | K41: 0 | L41: 3 | M41: 12x12 inches @ 1999.00 (-1) | 18x18 inches @ 2999.00 (0) | 24x24 inches @ 3999.00 (0) | N41: gid://shopify/ProductVariant/41872930668643 | O41: =TRUE() -> TRUE | P41: https://cdn.shopify.com/s/files/1/0572/0077/1171/files/NaturalElements.png?v=1756498129 | Q41: 2024-05-02 | R41: 2024-05-02 | S41: =TRUE() -> TRUE | T41: wall-dekoratif-tablo | U41: wall-art | V41: /products/wall-art/dekoratif-tablo.svg | W41: alias
A42: Diana | B42: dekoru-baupor | C42: gid://shopify/Product/7407079129187 | D42: ACTIVE | E42: Black Aesthetics | H42: 2D Wall-Art | Anime/Manga | Comics and Superheroes | Movies | Comics/Superheroes/Movies- 2D | I42: 5000 | J42: 5600 | K42: 0 | L42: 2 | M42: 12x18 inches @ 5000.00 (0) | 16x24 inches @ 5600.00 (0) | N42: gid://shopify/ProductVariant/41872942334051 | O42: =TRUE() -> TRUE | P42: https://cdn.shopify.com/s/files/1/0572/0077/1171/files/Dekoru-Bauporcopy.png?v=1756330368 | Q42: 2024-05-02 | R42: 2024-05-02 | S42: =FALSE() -> FALSE
A43: Eagle | B43: eagle | C43: gid://shopify/Product/7407081291875 | D43: ACTIVE | E43: Black Aesthetics | H43: 2D Wall-Art | Animals | I43: 2499 | J43: 2999 | K43: 0 | L43: 2 | M43: 10x18 inches @ 2499.00 (0) | 14x24 inches @ 2999.00 (0) | N43: gid://shopify/ProductVariant/41872950722659 | O43: =TRUE() -> TRUE | P43: https://cdn.shopify.com/s/files/1/0572/0077/1171/files/Eagle_c4d78179-54da-4486-9981-56a5be7a16be.png?v=1756385557 | Q43: 2024-05-02 | R43: 2024-05-02 | S43: =TRUE() -> TRUE | T43: wall-eagle | U43: wall-art | V43: /products/wall-art/eagle.svg | W43: exact
A44: Eagle Variant 2 | B44: eagle-1 | C44: gid://shopify/Product/7407084896355 | D44: ACTIVE | E44: Black Aesthetics | H44: 2D Wall-Art | Animals | I44: 2499 | J44: 5600 | K44: 0 | L44: 2 | M44: 12x16 inches @ 2499.00 (0) | 18x24 inches @ 5600.00 (0) | N44: gid://shopify/ProductVariant/41872964157539 | O44: =TRUE() -> TRUE | P44: https://cdn.shopify.com/s/files/1/0572/0077/1171/files/Eagle_Variant_2.png?v=1756385884 | Q44: 2024-05-02 | R44: 2024-05-02 | S44: =TRUE() -> TRUE | T44: wall-eagle-1 | U44: wall-art | V44: /products/wall-art/eagle-1.svg | W44: exact
A45: Elephant | B45: elephant | C45: gid://shopify/Product/7407086469219 | D45: ACTIVE | E45: Black Aesthetics | H45: 2D Wall-Art | Animals | I45: 3999 | J45: 3999 | K45: 0 | L45: 1 | M45: 20x24 inches @ 3999.00 (0) | N45: gid://shopify/ProductVariant/41972689666147 | O45: =TRUE() -> TRUE | P45: https://cdn.shopify.com/s/files/1/0572/0077/1171/files/Elephantcopy.png?v=1756388531 | Q45: 2024-05-02 | R45: 2024-05-02 | S45: =TRUE() -> TRUE | T45: wall-elephant | U45: wall-art | V45: /products/wall-art/elephant.svg | W45: exact
A46: Ethnic Ornaments | B46: ethnic-ornaments | C46: gid://shopify/Product/7407107670115 | D46: ACTIVE | E46: Black Aesthetics | H46: 2D Wall-Art | Minimalistic and Classical Art | Modern Art | Best Sellers | Cultural Arts | Cultural Arts- 2D | I46: 6999 | J46: 8999 | K46: 0 | L46: 2 | M46: 3 Panels: 6x18 inches each panel @ 6999.00 (0) | 3 Panels: 9x27 inches each panel @ 8999.00 (0) | N46: gid://shopify/ProductVariant/41873179246691 | O46: =TRUE() -> TRUE | P46: https://cdn.shopify.com/s/files/1/0572/0077/1171/files/EthnicOrnaments.png?v=1756497971 | Q46: 2024-05-02 | R46: 2024-05-02 | S46: =TRUE() -> TRUE | T46: wall-ethnic-ornaments | U46: wall-art | V46: /products/wall-art/ethnic-ornaments.svg | W46: exact
A47: Forest Wolf | B47: forest-wolf | C47: gid://shopify/Product/7407108358243 | D47: ACTIVE | E47: Black Aesthetics | H47: 2D Wall-Art | Animals | I47: 1999 | J47: 3999 | K47: 0 | L47: 3 | M47: 12x12 inches @ 1999.00 (0) | 18x18 inches @ 2999.00 (0) | 24x24 inches @ 3999.00 (0) | N47: gid://shopify/ProductVariant/41873185177699 | O47: =TRUE() -> TRUE | P47: https://cdn.shopify.com/s/files/1/0572/0077/1171/files/Forest_Wolf.png?v=1756406290 | Q47: 2024-05-02 | R47: 2024-05-02 | S47: =TRUE() -> TRUE | T47: wall-forrest-wolf | U47: wall-art | V47: /products/wall-art/forrest-wolf.svg | W47: alias
A48: Fox | B48: fox | C48: gid://shopify/Product/7407109898339 | D48: ACTIVE | E48: Black Aesthetics | H48: 2D Wall-Art | Animals | I48: 1999 | J48: 3999 | K48: 0 | L48: 3 | M48: 12x12 inches @ 1999.00 (0) | 18x18 inches @ 2999.00 (0) | 24x24 inches @ 3999.00 (0) | N48: gid://shopify/ProductVariant/41873210933347 | O48: =TRUE() -> TRUE | P48: https://cdn.shopify.com/s/files/1/0572/0077/1171/files/Fox_4e67e92b-33cc-4d81-9caf-7aa178af6900.png?v=1756406439 | Q48: 2024-05-02 | R48: 2024-05-02 | S48: =TRUE() -> TRUE | T48: wall-fox | U48: wall-art | V48: /products/wall-art/fox.svg | W48: exact
A49: Geometric Horse | B49: geometric-horse | C49: gid://shopify/Product/7407111176291 | D49: ACTIVE | E49: Black Aesthetics | H49: 2D Wall-Art | Animals | I49: 5000 | J49: 5600 | K49: 0 | L49: 2 | M49: 12x18 inches @ 5000.00 (0) | 16x24 inches @ 5600.00 (0) | N49: gid://shopify/ProductVariant/41873220141155 | O49: =TRUE() -> TRUE | P49: https://cdn.shopify.com/s/files/1/0572/0077/1171/files/Geometric_Horse.png?v=1756406864 | Q49: 2024-05-02 | R49: 2024-05-02 | S49: =TRUE() -> TRUE | T49: wall-geometric-horse | U49: wall-art | V49: /products/wall-art/geometric-horse.svg | W49: exact
A50: Globe | B50: globe | C50: gid://shopify/Product/7407112454243 | D50: ACTIVE | E50: Black Aesthetics | H50: 2D Wall-Art | I50: 2999 | J50: 3999 | K50: 0 | L50: 2 | M50: 18x18 inches @ 2999.00 (0) | 24x24 inches @ 3999.00 (0) | N50: gid://shopify/ProductVariant/41972861796451 | O50: =TRUE() -> TRUE | P50: https://cdn.shopify.com/s/files/1/0572/0077/1171/files/Globecopy.png?v=1756407370 | Q50: 2024-05-02 | R50: 2024-05-02 | S50: =TRUE() -> TRUE | T50: wall-globe | U50: wall-art | V50: /products/wall-art/globe.svg | W50: exact
A51: Indigenous | B51: indigenous-v-3 | C51: gid://shopify/Product/7407113470051 | D51: ACTIVE | E51: Black Aesthetics | H51: 2D Wall-Art | Cultural Arts- 2D | I51: 5600 | J51: 5600 | K51: 0 | L51: 1 | M51: 18x24 inches @ 5600.00 (0) | N51: gid://shopify/ProductVariant/41972902821987 | O51: =TRUE() -> TRUE | P51: https://cdn.shopify.com/s/files/1/0572/0077/1171/files/Indigenous.png?v=1756408487 | Q51: 2024-05-02 | R51: 2024-05-02 | S51: =TRUE() -> TRUE | T51: wall-indigenous-v-3 | U51: wall-art | V51: /products/wall-art/indigenous-v-3.svg | W51: exact
A52: Joker | B52: jocker | C52: gid://shopify/Product/7407114453091 | D52: ACTIVE | E52: Black Aesthetics | H52: 2D Wall-Art | Comics and Superheroes | Movies | Comics/Superheroes/Movies- 2D | I52: 5000 | J52: 5600 | K52: 0 | L52: 2 | M52: 12x18 inches @ 5000.00 (0) | 16x24 inches @ 5600.00 (-1) | N52: gid://shopify/ProductVariant/41873250189411 | O52: =TRUE() -> TRUE | P52: https://cdn.shopify.com/s/files/1/0572/0077/1171/files/Joker.png?v=1756409436 | Q52: 2024-05-02 | R52: 2024-05-02 | S52: =TRUE() -> TRUE | T52: wall-jocker | U52: wall-art | V52: /products/wall-art/jocker.svg | W52: exact
A53: Lightning Bolt | B53: lightning-bolt | C53: gid://shopify/Product/7407115763811 | D53: ACTIVE | E53: Black Aesthetics | H53: 2D Wall-Art | I53: 1999 | J53: 3999 | K53: 0 | L53: 3 | M53: 12x12 inches @ 1999.00 (0) | 18x18 inches @ 2999.00 (0) | 24x24 inches @ 3999.00 (0) | N53: gid://shopify/ProductVariant/41873261133923 | O53: =TRUE() -> TRUE | P53: https://cdn.shopify.com/s/files/1/0572/0077/1171/files/Lightning_Bolt.png?v=1756410838 | Q53: 2024-05-02 | R53: 2024-05-02 | S53: =TRUE() -> TRUE | T53: wall-lightning-bolt | U53: wall-art | V53: /products/wall-art/lightning-bolt.svg | W53: exact
A54: Michelangelo's David | B54: michelangelos-david | C54: gid://shopify/Product/7407116353635 | D54: ACTIVE | E54: Black Aesthetics | H54: 2D Wall-Art | Minimalistic and Classical Art | I54: 5600 | J54: 5600 | K54: 0 | L54: 1 | M54: 16x24 inches @ 5600.00 (0) | N54: gid://shopify/ProductVariant/41973099331683 | O54: =TRUE() -> TRUE | P54: https://cdn.shopify.com/s/files/1/0572/0077/1171/files/Michelangelo_s_David.png?v=1756412099 | Q54: 2024-05-02 | R54: 2024-05-02 | S54: =TRUE() -> TRUE | T54: wall-michelangelo-s-david | U54: wall-art | V54: /products/wall-art/michelangelo-s-david.svg | W54: exact
... A64: Fox Variant 2 | B64: fox-1 | C64: gid://shopify/Product/7407284125795 | D64: ACTIVE | E64: Black Aesthetics | H64: 2D Wall-Art | Animals | I64: 5000 | J64: 5600 | K64: 0 | L64: 2 | M64: 12x18 inches @ 5000.00 (0) | 16x24 inches @ 5600.00 (0) | N64: gid://shopify/ProductVariant/41874255609955 | O64: =TRUE() -> TRUE | P64: https://cdn.shopify.com/s/files/1/0572/0077/1171/files/Fox_Variant_2.png?v=1756406541 | Q64: 2024-05-02 | R64: 2024-05-02 | S64: =TRUE() -> TRUE | T64: wall-fox-1 | U64: wall-art | V64: /products/wall-art/fox-1.svg | W64: exact
A65: Hedera | B65: hedera | C65: gid://shopify/Product/7407284715619 | D65: ACTIVE | E65: Black Aesthetics | H65: 2D Wall-Art | Maths and Nature | I65: 4999 | J65: 5499 | K65: 0 | L65: 2 | M65: 3 Panels: 6x12 inches each panel @ 4999.00 (0) | 3 Panels: 12x24 inches each panel @ 5499.00 (0) | N65: gid://shopify/ProductVariant/41874256887907 | O65: =TRUE() -> TRUE | P65: https://cdn.shopify.com/s/files/1/0572/0077/1171/files/Hedera_e6c03393-7584-4291-9c8a-e64c942bad6b.png?v=1756498009 | Q65: 2024-05-02 | R65: 2024-05-02 | S65: =FALSE() -> FALSE
...

Sheet 3D Website Products
A1: Local Product ID | B1: Name | C1: Kind | D1: Nav Category | E1: Subcollections | F1: Local Asset | G1: Live On Shopify | H1: Shopify Handle | I1: Shopify Product GID | J1: Shopify Status | K1: Shopify Price (PKR) | L1: Variant GIDs | M1: Match Confidence
A2: wall-elegant-horse-head | B2: Elegant Horse Head | C2: wall-art | D2: wall-art | E2: animals | F2: /products/wall-art/elegant-horse-head.svg | G2: =TRUE() -> TRUE | H2: elegant-horse-head | I2: gid://shopify/Product/7407313879139 | J2: ACTIVE | K2: 2999 | L2: gid://shopify/ProductVariant/41972684423267 | gid://shopify/ProductVariant/41972684456035 | M2: exact
A3: wall-athena | B3: Athena | C3: wall-art | D3: wall-art | F3: /products/wall-art/athena.svg | G3: =TRUE() -> TRUE | H3: athena | I3: gid://shopify/Product/7407315714147 | J3: ACTIVE | K3: 2499 | L3: gid://shopify/ProductVariant/41963501224035 | gid://shopify/ProductVariant/41963501256803 | M3: exact
A4: wall-astronaut | B4: Astronaut | C4: wall-art | D4: wall-art | F4: /products/wall-art/astronaut.svg | G4: =TRUE() -> TRUE | H4: astronaut | I4: gid://shopify/Product/7407315091555 | J4: ACTIVE | K4: 3499 | L4: gid://shopify/ProductVariant/41963492769891 | gid://shopify/ProductVariant/41963492802659 | M4: exact
A5: wall-lion | B5: Lion | C5: wall-art | D5: wall-art | F5: /products/wall-art/lion.svg | G5: =TRUE() -> TRUE | H5: lion | I5: gid://shopify/Product/7407311814755 | J5: ACTIVE | K5: 5000 | L5: gid://shopify/ProductVariant/41874375442531 | gid://shopify/ProductVariant/41985866891363 | M5: exact
A6: wall-wolf | B6: Wolf | C6: wall-art | D6: wall-art | E6: animals | F6: /products/wall-art/wolf.svg | G6: =TRUE() -> TRUE | H6: wolf | I6: gid://shopify/Product/7405796851811 | J6: ACTIVE | K6: 2499 | L6: gid://shopify/ProductVariant/41867231035491 | gid://shopify/ProductVariant/41973148549219 | M6: exact
A7: wall-elephant | B7: Elephant | C7: wall-art | D7: wall-art | E7: animals | F7: /products/wall-art/elephant.svg | G7: =TRUE() -> TRUE | H7: elephant | I7: gid://shopify/Product/7407086469219 | J7: ACTIVE | K7: 3999 | L7: gid://shopify/ProductVariant/41972689666147 | M7: exact
A8: wall-abstract-cat | B8: Abstract Cat | C8: wall-art | D8: wall-art | E8: animals, minimalistic | F8: /products/wall-art/abstract-cat.svg | G8: =TRUE() -> TRUE | H8: cat-1 | I8: gid://shopify/Product/7405780041827 | J8: ACTIVE | K8: 1999 | L8: gid://shopify/ProductVariant/41966097662051 | gid://shopify/ProductVariant/41972520124515 | M8: exact
A9: wall-adera | B9: Adera | C9: wall-art | D9: wall-art | F9: /products/wall-art/adera.svg | G9: =TRUE() -> TRUE | H9: adera | I9: gid://shopify/Product/7405777748067 | J9: ACTIVE | K9: 2499 | L9: gid://shopify/ProductVariant/41921256980579 | M9: exact
A10: wall-amy-winehouse | B10: Amy Winehouse | C10: wall-art | D10: wall-art | E10: personalities | F10: /products/wall-art/amy-winehouse.svg | G10: =TRUE() -> TRUE | H10: amy-winehouse | I10: gid://shopify/Product/7407320694883 | J10: ACTIVE | K10: 5000 | L10: gid://shopify/ProductVariant/41963295244387 | gid://shopify/ProductVariant/41963295277155 | M10: exact
A11: wall-baby-groot | B11: Baby Groot | C11: wall-art | D11: wall-art | E11: comics-superheroes | F11: /products/wall-art/baby-groot.svg | G11: =TRUE() -> TRUE | H11: baby-groot | I11: gid://shopify/Product/7449001001059 | J11: ACTIVE | K11: 2499 | L11: gid://shopify/ProductVariant/42000415588451 | gid://shopify/ProductVariant/42000415621219 | M11: exact
A12: wall-batman-dc-superhero | B12: Batman DC Superhero | C12: wall-art | D12: wall-art | E12: comics-superheroes | F12: /products/wall-art/batman-dc-superhero.svg | G12: =TRUE() -> TRUE | H12: batman-dc-superhero | I12: gid://shopify/Product/7449006211171 | J12: ACTIVE | K12: 1999 | L12: gid://shopify/ProductVariant/42000423714915 | gid://shopify/ProductVariant/42000423747683 | gid://shopify/ProductVariant/42000423780451 | M12: exact
A13: wall-batman-and-joker | B13: Batman and Joker | C13: wall-art | D13: wall-art | E13: comics-superheroes | F13: /products/wall-art/batman-and-joker.svg | G13: =TRUE() -> TRUE | H13: batman-and-joker | I13: gid://shopify/Product/7449003163747 | J13: ACTIVE | K13: 2499 | L13: gid://shopify/ProductVariant/42000419061859 | gid://shopify/ProductVariant/42000419094627 | M13: exact
A14: wall-bee | B14: Bee | C14: wall-art | D14: wall-art | E14: animals | F14: /products/wall-art/bee.svg | G14: =TRUE() -> TRUE | H14: bee | I14: gid://shopify/Product/7407053537379 | J14: ACTIVE | K14: 2499 | L14: gid://shopify/ProductVariant/41963553718371 | gid://shopify/ProductVariant/41963553751139 | M14: exact
A15: wall-bob-marley | B15: Bob Marley | C15: wall-art | D15: wall-art | E15: personalities | F15: /products/wall-art/bob-marley.svg | G15: =TRUE() -> TRUE | H15: bob-marley | I15: gid://shopify/Product/7407316467811 | J15: ACTIVE | K15: 1999 | L15: gid://shopify/ProductVariant/41965529137251 | gid://shopify/ProductVariant/41965529170019 | gid://shopify/ProductVariant/41965529202787 | M15: exact
A16: wall-boba-fett | B16: Boba Fett | C16: wall-art | D16: wall-art | E16: comics-superheroes | F16: /products/wall-art/boba-fett.svg | G16: =TRUE() -> TRUE | H16: boba-fatt | I16: gid://shopify/Product/7407316172899 | J16: ACTIVE | K16: 1999 | L16: gid://shopify/ProductVariant/41965569343587 | gid://shopify/ProductVariant/41972459044963 | gid://shopify/ProductVariant/41965569376355 | M16: exact
A17: wall-bull | B17: Bull | C17: wall-art | D17: wall-art | E17: animals | F17: /products/wall-art/bull.svg | G17: =TRUE() -> TRUE | H17: bull | I17: gid://shopify/Product/7405779452003 | J17: ACTIVE | K17: 2499 | L17: gid://shopify/ProductVariant/41965720862819 | gid://shopify/ProductVariant/41965720895587 | M17: exact
A18: wall-butterfly | B18: Butterfly | C18: wall-art | D18: wall-art | E18: animals | F18: /products/wall-art/butterfly.svg | G18: =TRUE() -> TRUE | H18: butterfly | I18: gid://shopify/Product/7407054553187 | J18: ACTIVE | K18: 1999 | L18: gid://shopify/ProductVariant/41965797113955 | gid://shopify/ProductVariant/41972475854947 | gid://shopify/ProductVariant/41965797146723 | M18: exact
A19: wall-cat | B19: Cat | C19: wall-art | D19: wall-art | E19: animals | F19: /products/wall-art/cat.svg | G19: =TRUE() -> TRUE | H19: cat | I19: gid://shopify/Product/7405779779683 | J19: ACTIVE | K19: 1999 | L19: gid://shopify/ProductVariant/41867185684579 | gid://shopify/ProductVariant/41972504232035 | gid://shopify/ProductVariant/41972504264803 | M19: exact
A20: wall-circle-of-life | B20: Circle of Life | C20: wall-art | D20: wall-art | E20: minimalistic | F20: /products/wall-art/circle-of-life.svg | G20: =TRUE() -> TRUE | H20: circle-of-life | I20: gid://shopify/Product/7405780402275 | J20: ACTIVE | K20: 1999 | L20: gid://shopify/ProductVariant/41966121255011 | gid://shopify/ProductVariant/41966121287779 | gid://shopify/ProductVariant/41966121320547 | M20: exact
A21: wall-climber | B21: Climber | C21: wall-art | D21: wall-art | F21: /products/wall-art/climber.svg | G21: =TRUE() -> TRUE | H21: climber | I21: gid://shopify/Product/7407321448547 | J21: ACTIVE | K21: 2499 | L21: gid://shopify/ProductVariant/41966169489507 | gid://shopify/ProductVariant/41966169522275 | M21: exact
A22: wall-cowboy | B22: Cowboy | C22: wall-art | D22: wall-art | E22: movies-pop | F22: /products/wall-art/cowboy.svg | G22: =TRUE() -> TRUE | H22: cowboy | I22: gid://shopify/Product/7405785940067 | J22: ACTIVE | K22: 5000 | L22: gid://shopify/ProductVariant/41966215397475 | gid://shopify/ProductVariant/41966215430243 | M22: exact
A23: wall-decor-horse | B23: Decor Horse | C23: wall-art | D23: wall-art | E23: animals, minimalistic | F23: /products/wall-art/decor-horse.svg | G23: =TRUE() -> TRUE | H23: decor-hourse | I23: gid://shopify/Product/7407322103907 | J23: ACTIVE | K23: 4499 | L23: gid://shopify/ProductVariant/41966262780003 | gid://shopify/ProductVariant/41966262812771 | gid://shopify/ProductVariant/41966262845539 | M23: exact
A24: wall-deer-head | B24: Deer Head | C24: wall-art | D24: wall-art | E24: animals | F24: /products/wall-art/deer-head.svg | G24: =TRUE() -> TRUE | H24: dear-head | I24: gid://shopify/Product/7407314370659 | J24: ACTIVE | K24: 1999 | L24: gid://shopify/ProductVariant/41966249541731 | gid://shopify/ProductVariant/41966249574499 | gid://shopify/ProductVariant/41966249607267 | M24: exact
A25: wall-dolphin | B25: Dolphin | C25: wall-art | D25: wall-art | E25: animals | F25: /products/wall-art/dolphin.svg | G25: =TRUE() -> TRUE | H25: dolphin | I25: gid://shopify/Product/7407314239587 | J25: ACTIVE | K25: 1999 | L25: gid://shopify/ProductVariant/41874388811875 | gid://shopify/ProductVariant/41971868205155 | gid://shopify/ProductVariant/41971868237923 | M25: exact
A26: wall-eagle | B26: Eagle | C26: wall-art | D26: wall-art | E26: animals | F26: /products/wall-art/eagle.svg | G26: =TRUE() -> TRUE | H26: eagle | I26: gid://shopify/Product/7407081291875 | J26: ACTIVE | K26: 2499 | L26: gid://shopify/ProductVariant/41872950722659 | gid://shopify/ProductVariant/41972637270115 | M26: exact
A27: wall-family-tree | B27: Family Tree | C27: wall-art | D27: wall-art | F27: /products/wall-art/family-tree.svg | G27: =TRUE() -> TRUE | H27: family-tree | I27: gid://shopify/Product/7407313616995 | J27: ACTIVE | K27: 5600 | L27: gid://shopify/ProductVariant/41972805795939 | M27: exact
A28: wall-flower-floral | B28: Flower Floral | C28: wall-art | D28: wall-art | E28: minimalistic | F28: /products/wall-art/flower-floral.svg | G28: =TRUE() -> TRUE | H28: flower-floral | I28: gid://shopify/Product/7407313092707 | J28: ACTIVE | K28: 3999 | L28: gid://shopify/ProductVariant/41972816052323 | M28: exact
A29: wall-flower-of-life | B29: Flower of Life | C29: wall-art | D29: wall-art | E29: minimalistic | F29: /products/wall-art/flower-of-life.svg | G29: =TRUE() -> TRUE | H29: flower-of-life | I29: gid://shopify/Product/7407313420387 | J29: ACTIVE | K29: 1999 | L29: gid://shopify/ProductVariant/41874387140707 | gid://shopify/ProductVariant/41972820148323 | gid://shopify/ProductVariant/41972820181091 | M29: exact
A30: wall-fox | B30: Fox | C30: wall-art | D30: wall-art | E30: animals | F30: /products/wall-art/fox.svg | G30: =TRUE() -> TRUE | H30: fox | I30: gid://shopify/Product/7407109898339 | J30: ACTIVE | K30: 1999 | L30: gid://shopify/ProductVariant/41873210933347 | gid://shopify/ProductVariant/41972827881571 | gid://shopify/ProductVariant/41972827914339 | M30: exact
A31: wall-geometric-heart | B31: Geometric Heart | C31: wall-art | D31: wall-art | E31: minimalistic | F31: /products/wall-art/geometric-heart.svg | G31: =TRUE() -> TRUE | H31: geometric-heart | I31: gid://shopify/Product/7407312732259 | J31: ACTIVE | K31: 1999 | L31: gid://shopify/ProductVariant/41874381078627 | gid://shopify/ProductVariant/41972852850787 | gid://shopify/ProductVariant/41972852883555 | M31: exact
A32: wall-geometric-horse | B32: Geometric Horse | C32: wall-art | D32: wall-art | E32: animals, minimalistic | F32: /products/wall-art/geometric-horse.svg | G32: =TRUE() -> TRUE | H32: geometric-horse | I32: gid://shopify/Product/7407111176291 | J32: ACTIVE | K32: 5000 | L32: gid://shopify/ProductVariant/41873220141155 | gid://shopify/ProductVariant/41972858126435 | M32: exact
A33: wall-gojo | B33: Gojo | C33: wall-art | D33: wall-art | E33: anime-manga | F33: /products/wall-art/gojo.svg | G33: =TRUE() -> TRUE | H33: symbiotic-energy-of-venom | I33: gid://shopify/Product/7449105203299 | J33: ACTIVE | K33: 5000 | L33: gid://shopify/ProductVariant/42000595288163 | gid://shopify/ProductVariant/42000595320931 | M33: exact
A34: wall-hamsa | B34: Hamsa | C34: wall-art | D34: wall-art | E34: cultural | F34: /products/wall-art/hamsa.svg | G34: =TRUE() -> TRUE | H34: hamsa | I34: gid://shopify/Product/7407322398819 | J34: ACTIVE | K34: 5000 | L34: gid://shopify/ProductVariant/41874408341603 | gid://shopify/ProductVariant/41972877459555 | M34: exact
A35: wall-horse | B35: Horse | C35: wall-art | D35: wall-art | E35: animals | F35: /products/wall-art/horse.svg | G35: =TRUE() -> TRUE | H35: horse | I35: gid://shopify/Product/7407286124643 | J35: ACTIVE | K35: 5000 | L35: gid://shopify/ProductVariant/41874259968099 | gid://shopify/ProductVariant/41972894859363 | M35: exact
A36: wall-kakashi | B36: Kakashi | C36: wall-art | D36: wall-art | E36: anime-manga | F36: /products/wall-art/kakashi.svg | G36: =TRUE() -> TRUE | H36: kaico | I36: gid://shopify/Product/7449011519587 | J36: ACTIVE | K36: 5000 | L36: gid://shopify/ProductVariant/42000432365667 | gid://shopify/ProductVariant/42000432398435 | M36: exact
A37: wall-leaf-set-v1 | B37: Leaf Set V1 | C37: wall-art | D37: wall-art | E37: minimalistic | F37: /products/wall-art/leaf-set-v1.svg | G37: =TRUE() -> TRUE | H37: leaf-set-v1 | I37: gid://shopify/Product/7407312306275 | J37: ACTIVE | K37: 6999 | L37: gid://shopify/ProductVariant/41874380095587 | gid://shopify/ProductVariant/41972945911907 | M37: exact
A38: wall-leaf-set-v2 | B38: Leaf Set V2 | C38: wall-art | D38: wall-art | E38: minimalistic | F38: /products/wall-art/leaf-set-v2.svg | G38: =TRUE() -> TRUE | H38: leaf-set-v2 | I38: gid://shopify/Product/7407311978595 | J38: ACTIVE | K38: 7999 | L38: gid://shopify/ProductVariant/41874375901283 | M38: exact
A39: wall-love-heart | B39: Love Heart | C39: wall-art | D39: wall-art | E39: minimalistic | F39: /products/wall-art/love-heart.svg | G39: =FALSE() -> FALSE | M39: NO MATCH
A40: wall-marilyn-monroe | B40: Marilyn Monroe | C40: wall-art | D40: wall-art | E40: personalities | F40: /products/wall-art/marilyn-monroe.svg | G40: =TRUE() -> TRUE | H40: marilyn-monroe | I40: gid://shopify/Product/7407323545699 | J40: ACTIVE | K40: 2499 | L40: gid://shopify/ProductVariant/41874412568675 | gid://shopify/ProductVariant/41973088682083 | M40: exact
...

Sheet Shopify Collections
A1: Sort | B1: Collection Title | C1: Handle | D1: Collection GID | E1: Nav Category (3D site) | F1: Products | G1: Matched To Local | H1: Sample Products (first 8 handles)
A2: 1 | B2: 2D Wall-Art | C2: 2d-wallart | D2: gid://shopify/Collection/276274217059 | E2: wall-art | F2: 192 | G2: 141 | H2: ninja, mk4-toyota, ronaldo, kaico, nissan, m2-marla-singer, athena, dragon-ball-goku-1
A3: 2 | B3: Animals | C3: animal-2d-wall-art | D3: gid://shopify/Collection/276867317859 | E3: wall-art | F3: 54 | G3: 42 | H3: elegant-horse-head, welters-monkey, owl-1, wolf-2, cat-eyes, cat-greyscale, blue-fish, orange-fish
A4: 3 | B4: Anime/Manga | C4: anime-mangaall | D4: gid://shopify/Collection/276977385571 | E4: — | F4: 91 | G4: 12 | H4: ninja, kaico, dragon-ball-goku-1, realistic-demon-slayer-rengoku, naruto-in-the-dark, jiraiya-the-sage, jiraiya-and-pain, itachi-black-on-red
A5: 4 | B5: Comics and Superheroes | C5: comics-and-superheroes-2d | D5: gid://shopify/Collection/276977418339 | E5: wall-art | F5: 24 | G5: 12 | H5: venom, joker-dark-knight, black-panther-1, new-2, ironman, jocker, joker-black-and-white, joker-disobey
A6: 5 | B6: Maths and Nature | C6: maths-and-nature | D6: gid://shopify/Collection/276977582179 | E6: wall-art | F6: 27 | G6: 22 | H6: decor-wall-frames, lucid, mode, silva, circle-of-life, adera, four-quls-tree, cat-4
A7: 6 | B7: Minimalistic and Classical Art | C7: minimalistic | D7: gid://shopify/Collection/276977614947 | E7: wall-art | F7: 42 | G7: 20 | H7: athena, roman-colloseum-painting-set, africans, abstract-calligraphy, abstract, themis-v-1, creation-of-adam, lucid
A8: 7 | B8: Personalities | C8: personalities | D8: gid://shopify/Collection/276977778787 | E8: wall-art | F8: 20 | G8: 12 | H8: ronaldo, m2-marla-singer, ronaldo-cr7, bob-marley, ronaldo-1, messi, marilyn-monroe, tupac-2pac
A9: 8 | B9: Movies | C9: movies | D9: gid://shopify/Collection/276978991203 | E9: wall-art | F9: 37 | G9: 19 | H9: venom, joker-dark-knight, black-panther-1, new-2, ironman, marilyn-monroe, boba-fatt, jocker
A10: 9 | B10: Modern Art | C10: modern-culture | D10: gid://shopify/Collection/276979875939 | E10: wall-art | F10: 70 | G10: 40 | H10: athena, abstract-faces-variant-2, roman-colloseum-painting-set, world-map-route, africans, abstract-calligraphy, abstract, creation-of-adam
A11: 10 | B11: Digital Art | C11: poster-art | D11: gid://shopify/Collection/277622194275 | E11: digital-art | F11: 240 | G11: 19 | H11: electric-grace-neon-smoking-lady, rumi-whirling-dervishes-1, lady-stained-glass-style, paki-smoker-ladies-1, roman-colloseum-painting-set, rumi-whirling-dervishes, neon-noir-neon-smoking-lady, vector-diva-neon-smoking-lady
A12: 11 | B12: Best Sellers | C12: best-seller | D12: gid://shopify/Collection/286312890467 | E12: — | F12: 38 | G12: 11 | H12: rumi-whirling-dervishes-1, lady-stained-glass-style, abstract-faces-variant-2, roman-colloseum-painting-set, africans, deter, bear-copy, grey-wolf-copy
A13: 12 | B13: New Arrivals | C13: new-arrivals | D13: gid://shopify/Collection/286313185379 | E13: — | F13: 68 | G13: 15 | H13: lady-stained-glass-style, abstract-faces-variant-2, roman-colloseum-painting-set, ferrari-2, lighthouse-stained-glass-style, bear-copy, grey-wolf-copy, grey-wolf
... A37: 36 | B37: T-Shirts- Contrast Whisper | C37: contract-whisper | D37: gid://shopify/Collection/295597342819 | E37: apparel | F37: 20 | G37: 0 | H37: peace-doodle, foodie-bear-copy, foodie-bear, doodles-3, doodles-2, doodles-1, cat-doodle, astronaut-doodle-2
A38: 37 | B38: T-Shirts- Doodle Art | C38: t-shirts-doodle-art | D38: gid://shopify/Collection/295597604963 | E38: apparel | F38: 0 | G38: 0
A39: 38 | B39: T-Shirts- Pop Art | C39: t-shirts-pop-art | D39: gid://shopify/Collection/295597768803 | E39: apparel | F39: 10 | G39: 0 | H39: sakht-launda, pindi-boy-1, missile-pop-art, girl-pop-art, car-pop-art, pindi-boy-2, medusa, godfather-skeleton

Sheet Unmatched
A1: 3D-website products with NO live Shopify product (need creating in Shopify or intentional local-only)
A2: Local Product ID | B2: Name | C2: Kind | D2: Category | E2: Local Asset
A3: wall-love-heart | B3: Love Heart | C3: wall-art | D3: wall-art | E3: /products/wall-art/love-heart.svg
A4: wall-lady-diana | B4: Lady Diana | C4: wall-art | D4: wall-art | E4: /products/wall-art/lady-diana.svg
A5: wall-love-heart-tree | B5: Love heart Tree | C5: wall-art | D5: wall-art | E5: /products/wall-art/love-heart-tree.svg
A6: wall-love-tree | B6: Love tree | C6: wall-art | D6: wall-art | E6: /products/wall-art/love-tree.svg
A7: digital-madara-sharingan | B7: Madara Sharingan | C7: digital | D7: digital-art | E7: /products/digital/final/madara-sharingan.jpg
A8: digital-roman-colosseum-i | B8: Roman Colosseum I | C8: digital | D8: digital-art | E8: /products/digital/final/roman-colosseum-i.jpg
A9: digital-roman-colosseum-ii | B9: Roman Colosseum II | C9: digital | D9: digital-art | E9: /products/digital/final/roman-colosseum-ii.jpg
A10: digital-roman-colosseum-iii | B10: Roman Colosseum III | C10: digital | D10: digital-art | E10: /products/digital/final/roman-colosseum-iii.jpg
A11: digital-neon-smoking-lady | B11: Neon Smoking Lady | C11: digital | D11: digital-art | E11: /products/digital/final/neon-smoking-lady.jpg
A12: digital-smoking-lady-neon | B12: Smoking Lady Neon | C12: digital | D12: digital-art | E12: /products/digital/final/smoking-lady-neon.jpg
A13: digital-smoking-lady-variant | B13: Smoking Lady Variant | C13: digital | D13: digital-art | E13: /products/digital/final/smoking-lady-variant.jpg
A14: layered-motorcycle | B14: Motorcycle Wall Panel | C14: layered | D14: layered-art
A15: object-panther | B15: Panther | C15: object | D15: 3d-objects | E15: /products/3d/panther.stl
A16: object-fidget-central-gear | B16: Fidget Central Gear | C16: object | D16: 3d-objects | E16: /products/3d/fidget-central-gear.stl
A17: object-batarang-6mm | B17: Batarang 6mm | C17: object | D17: 3d-objects | E17: /products/3d/batarang-6mm.stl
A18: object-batman-bookmark | B18: Batman Bookmark | C18: object | D18: 3d-objects | E18: /products/3d/batman-bookmark.stl
A19: object-picture-frame-corner-2mm | B19: Picture Frame Corner 2mm | C19: object | D19: 3d-objects | E19: /products/3d/picture-frame-corner-2mm.stl
A20: object-picture-frame-corner-3mm | B20: Picture Frame Corner 3mm | C20: object | D20: 3d-objects | E20: /products/3d/picture-frame-corner-3mm.stl
A21: object-mini-joker | B21: Mini Joker 80mm | C21: object | D21: 3d-objects | E21: /products/3d/mini-joker.stl
A22: object-mini-superman | B22: Mini Superman 80mm | C22: object | D22: 3d-objects | E22: /products/3d/mini-superman.stl
A23: object-flexi-cat | B23: Flexi Cat | C23: object | D23: 3d-objects | E23: /products/3d/flexi-cat.stl
A24: object-lamp-base | B24: Lamp Base | C24: object | D24: 3d-objects | E24: /products/3d/lamp-base.stl
A25: object-batman-figure-130mm | B25: Batman Figure 130mm | C25: object | D25: 3d-objects | E25: /products/3d/batman-figure-130mm.stl
A26: object-batman-stand-150mm | B26: Batman Stand 150mm | C26: object | D26: 3d-objects | E26: /products/3d/batman-stand-150mm.stl
A27: object-mini-batman-90mm | B27: Mini Batman 90mm | C27: object | D27: 3d-objects | E27: /products/3d/mini-batman-90mm.stl
A30: Live Shopify products NOT in the 3D website: 340 (full list on 'Shopify Live Products' sheet, filter 'In 3D Website' = FALSE — mostly Apparel/T-Shirts, Islamic Art frames, and set paintings)
